# 错误处理

打开文件的函数 `open()` ，成功时返回文件描述符（就是一个整数），出错时返回 `-1`

`try...except...finally...` 错误处理机制



```python
try:
    print('try...')
    r = 10 / 0
    print('result:',r)
except ZeroDivisionError as e:
    print('except:',e)
finally:
    print('finally...')
print('END')
```



```python
#多个except的情况
try:
    print('try...')
    r = 10 / int('a')
    print('result:', r)
except ValueError as e:
    print('ValueError:', e)
except ZeroDivisionError as e:
    print('ZeroDivisionError:', e)
finally:
    print('finally...')
print('END')
```



如果没有错误发生，可以在 `except` 语句块后面加一个 `else` 。当没有错误发生时，会自动执行 `else` 语句

```python
try:
    print('try...')
    r = 10 / int('2')
    print('result:', r)
except ValueError as e:
    print('ValueError:', e)
except ZeroDivisionError as e:
    print('ZeroDivisionError:', e)
else:
    print('no error!')
finally:
    print('finally...')
print('END')
```



使用`try...except`捕获错误还有一个巨大的好处，就是可以跨越多层调用，比如函数`main()`调用`foo()`，`foo()`调用`bar()`，结果`bar()`出错了，这时，只要`main()`捕获到了，就可以处理：



```python
def foo(s):
    return 10 / int(s)

def bar(s):
    return foo(s) * 2

def main():
    try:
        bar('0')
    except Exception as e:
        print('Error:', e)
    finally:
        print('finally...')
```

也就是说，不需要在每个可能出错的地方去捕获错误，只要在合适的层次去捕获错误就可以了。这样一来，就大大减少了写`try...except...finally`的麻烦。



## 调用栈

> 如果错误没有被捕获，错误就会一直往上抛，最后被 Python 解释器捕获，打印一个错误信息，然后程序退出



```python
# err.py:
def foo(s):
    return 10 / int(s)

def bar(s):
    return foo(s) * 2

def main():
    bar('0')

main()

$ python3 err.py
Traceback (most recent call last):
  File "err.py", line 11, in <module>
    main()
  File "err.py", line 9, in main
    bar('0')
  File "err.py", line 6, in bar
    return foo(s) * 2
  File "err.py", line 3, in foo
    return 10 / int(s)
ZeroDivisionError: division by zero
```



## 抛出错误

> 因为错误是class，捕获一个错误就是捕获到该class的一个实例
>
> 可以定一个错误的class，选择好继承关系，然后用 raise 语句抛出一个错误的实例



```python
class FooError(ValueError):
    pass

def foo(s):
    n = int(s)
    if n == 0:
        raise FooError('invalid value: %s' %s)
    return 10 / n

foo('0')
```



```python
def foo(s):
    n = int(s)
    if n==0:
        raise ValueError('invalid value: %s' % s)
    return 10 / n

def bar():
    try:
        foo('0')
    except ValueError as e:
        print('ValueError!')
        raise

bar()
```



`raise` 语句如果不带参数，就会把当前错误原样抛出。



## 小结

Python 内置的 `try..except..finally` 用来处理错误十分方便。程序也可以主动抛出错误，让调用者来处理相应的错误。



